<?xml version="1.0"?>
<robot xmlns:xacro="http://ros.org/wiki/xacro">

  <!-- =============== Constants =============== -->
  <xacro:property name="arm_type"       value="TRBA-R-004-7"/>
  <xacro:property name="vis_mesh_scale" value="1.0 1.0 1.0"/>
  <xacro:property name="col_mesh_scale" value="0.01 0.01 0.01"/>

  <!-- =============== Load Dependencies =============== -->
  <xacro:include filename="$(find torobo_resources)/urdf/common.xacro" />
  <xacro:include filename="$(find torobo_resources)/urdf/arm/arm_common.gazebo.xacro" />

  <!-- =============== Link & Joint =============== -->
  <xacro:macro name="arm_v0" params="prefix parent *joint_origin">

    <joint name="${prefix}arm/root" type="fixed">
      <xacro:insert_block name="joint_origin"/>
      <parent link="${parent}"/>
      <child link="${prefix}arm/link_0"/>
    </joint>

    <link name="${prefix}arm/link_0">
      <visual>
        <geometry>
          <mesh filename="package://torobo_resources/meshes/arm/${arm_type}/DAE/link0.dae" scale="${vis_mesh_scale}"/>
        </geometry>
        <origin xyz="0 0 0"/>
        <material name="white"/>
      </visual>
      <collision>
        <geometry>
          <mesh filename="package://torobo_resources/meshes/arm/${arm_type}/STL/link0.stl" scale="${col_mesh_scale}"/>
        </geometry>
        <origin xyz="0 0 0"/>
      </collision>
      <inertial>
        <origin xyz="-0.000436 0.000019 0.041708"/>	
        <mass value="2.545036"/>	
        <inertia	
          ixx="6.331898e-3" ixy="2.399900e-6" ixz="-3.132040e-5"	
          iyy="6.434612e-3" iyz="1.515900e-6" izz="8.449834e-3"/>	
      </inertial>
    </link>

    <joint name="${prefix}arm/joint_1" type="revolute">
      <parent link="${prefix}arm/link_0"/>
      <child link="${prefix}arm/link_1"/>
      <origin xyz="0 0 0.220" rpy="0 0 0"/>
      <axis xyz="0 0 1"/>
      <limit lower="${-170*M_PI/180}" upper="${170*M_PI/180}" effort="110" velocity="${100*M_PI/180}"/>
    </joint>

    <link name="${prefix}arm/link_1">
      <visual>
        <geometry>
          <mesh filename="package://torobo_resources/meshes/arm/${arm_type}/DAE/link1.dae" scale="${vis_mesh_scale}"/>
        </geometry>
        <material name="white"/>
      </visual>
      <collision>
        <geometry>
          <mesh filename="package://torobo_resources/meshes/arm/${arm_type}/STL/link1.stl" scale="${col_mesh_scale}"/>
        </geometry>
      </collision>
      <inertial>
        <origin xyz="0.000009 0.004526 -0.062965"/>	
        <mass value="4.553552"/>	
        <inertia	
          ixx="2.644887e-2" ixy="5.349000e-7" ixz="4.084800e-6"	
          iyy="2.675988e-2" iyz="-8.294709e-4" izz="7.305179e-3"/>	
      </inertial>
    </link>

    <joint name="${prefix}arm/joint_2" type="revolute">
      <parent link="${prefix}arm/link_1"/>
      <child link="${prefix}arm/link_2"/>
      <origin xyz="0 0 0" rpy="${-90*M_PI/180} 0 0"/>
      <axis xyz="0 0 1"/>
      <limit lower="${-110*M_PI/180}" upper="${110*M_PI/180}" effort="110" velocity="${100*M_PI/180}"/>
    </joint>

    <link name="${prefix}arm/link_2">
      <visual>
        <geometry>
          <mesh filename="package://torobo_resources/meshes/arm/${arm_type}/DAE/link2.dae" scale="${vis_mesh_scale}"/>
        </geometry>
        <material name="white"/>
      </visual>
      <collision>
        <geometry>
          <mesh filename="package://torobo_resources/meshes/arm/${arm_type}/STL/link2.stl" scale="${col_mesh_scale}"/>
        </geometry>
      </collision>
      <inertial>
        <origin xyz="0.000000 -0.064474 -0.016924"/>	
        <mass value="2.474676"/>	
        <inertia	
          ixx="1.163631e-2" ixy="-6.892000e-7" ixz="2.103000e-7"	
          iyy="4.853435e-3" iyz="2.196366e-3" izz="1.202305e-2"/>	
      </inertial>
    </link>

    <joint name="${prefix}arm/joint_3" type="revolute">
      <parent link="${prefix}arm/link_2"/>
      <child link="${prefix}arm/link_3"/>
      <origin xyz="0 -0.3 0" rpy="${90*M_PI/180} 0 0"/>
      <axis xyz="0 0 1"/>
      <limit lower="${-165*M_PI/180}" upper="${165*M_PI/180}" effort="70" velocity="${150*M_PI/180}"/>
    </joint>

    <link name="${prefix}arm/link_3">
      <visual>
        <geometry>
          <mesh filename="package://torobo_resources/meshes/arm/${arm_type}/DAE/link3.dae" scale="${vis_mesh_scale}"/>
        </geometry>
        <material name="white"/>
      </visual>
      <collision>
        <geometry>
          <mesh filename="package://torobo_resources/meshes/arm/${arm_type}/STL/link3.stl" scale="${col_mesh_scale}"/>
        </geometry>
      </collision>
      <inertial>
        <origin xyz="0.000012 0.005769 -0.066866"/>	
        <mass value="3.237919"/>	
        <inertia	
          ixx="1.911238e-2" ixy="2.978000e-7" ixz="-4.962600e-6"	
          iyy="1.915428e-2" iyz="-7.716287e-4" izz="3.920768e-3"/>	
      </inertial>
    </link>

    <joint name="${prefix}arm/joint_4" type="revolute">
      <parent link="${prefix}arm/link_3"/>
      <child link="${prefix}arm/link_4"/>
      <origin xyz="0 0 0" rpy="${-90*M_PI/180} 0 0"/>
      <axis xyz="0 0 1"/>
      <limit lower="${-125*M_PI/180}" upper="${125*M_PI/180}" effort="70" velocity="${150*M_PI/180}"/>
    </joint>

    <link name="${prefix}arm/link_4">
      <visual>
        <geometry>
          <mesh filename="package://torobo_resources/meshes/arm/${arm_type}/DAE/link4.dae" scale="${vis_mesh_scale}"/>
        </geometry>
        <material name="white"/>
      </visual>
      <collision>
        <geometry>
          <mesh filename="package://torobo_resources/meshes/arm/${arm_type}/STL/link4.stl" scale="${col_mesh_scale}"/>
        </geometry>
      </collision>
      <inertial>
        <origin xyz="0.000006 -0.062765 -0.018379"/>	
        <mass value="1.945562"/>	
        <inertia	
          ixx="9.626170e-3" ixy="-1.551000e-7" ixz="1.278000e-7"	
          iyy="2.996661e-3" iyz="1.733720e-3" izz="9.870906e-3"/>	
      </inertial>
    </link>

    <joint name="${prefix}arm/joint_5" type="revolute">
      <parent link="${prefix}arm/link_4"/>
      <child link="${prefix}arm/link_5"/>
      <origin xyz="0 -0.3 0" rpy="${90*M_PI/180} 0 0"/>
      <axis xyz="0 0 1"/>
      <limit lower="${-165*M_PI/180}" upper="${165*M_PI/180}" effort="30" velocity="${160*M_PI/180}"/>
    </joint>

    <link name="${prefix}arm/link_5">
      <visual>
        <geometry>
          <mesh filename="package://torobo_resources/meshes/arm/${arm_type}/DAE/link5.dae" scale="${vis_mesh_scale}"/>
        </geometry>
        <material name="white"/>
      </visual>
      <collision>
        <geometry>
          <mesh filename="package://torobo_resources/meshes/arm/${arm_type}/STL/link5.stl" scale="${col_mesh_scale}"/>
        </geometry>
      </collision>
      <inertial>
        <origin xyz="-0.000009 0.010041 -0.094026"/>	
        <mass value="1.798056"/>	
        <inertia	
          ixx="9.196412e-3" ixy="2.212000e-7" ixz="6.890000e-7"	
          iyy="9.130626e-3" iyz="-1.559966e-3" izz="1.957429e-3"/>	
      </inertial>
    </link>

    <joint name="${prefix}arm/joint_6" type="revolute">
      <parent link="${prefix}arm/link_5"/>
      <child link="${prefix}arm/link_6"/>
      <origin xyz="0 0 0" rpy="${-90*M_PI/180} 0 0"/>
      <axis xyz="0 0 1"/>
      <limit lower="${-120*M_PI/180}" upper="${120*M_PI/180}" effort="30" velocity="${160*M_PI/180}"/>
    </joint>

    <link name="${prefix}arm/link_6">
      <visual>
        <geometry>
          <mesh filename="package://torobo_resources/meshes/arm/${arm_type}/DAE/link6.dae" scale="${vis_mesh_scale}"/>
        </geometry>
        <material name="white"/>
      </visual>
      <collision>
        <geometry>
          <mesh filename="package://torobo_resources/meshes/arm/${arm_type}/STL/link6.stl" scale="${col_mesh_scale}"/>
        </geometry>
      </collision>
      <inertial>      
      <origin xyz="0.000002 -0.050748 -0.002319"/>	
        <mass value="2.271792"/>	
        <inertia	
          ixx="8.528173e-3" ixy="-5.321000e-7" ixz="4.298000e-7"	
          iyy="2.242304e-3" iyz="1.159234e-4" izz="8.444133e-3"/>	
      </inertial>
    </link>

    <joint name="${prefix}arm/joint_7" type="revolute">
      <parent link="${prefix}arm/link_6"/>
      <child link="${prefix}arm/link_7"/>
      <origin xyz="0 -0.170 0" rpy="${90*M_PI/180} 0 0"/>
      <axis xyz="0 0 1"/>
      <limit lower="${-170*M_PI/180}" upper="${170*M_PI/180}" effort="15" velocity="${240*M_PI/180}"/>
    </joint>
  
    <link name="${prefix}arm/link_7">
      <visual>
        <geometry>
          <mesh filename="package://torobo_resources/meshes/arm/${arm_type}/DAE/link7.dae" scale="${vis_mesh_scale}"/>
        </geometry>
        <material name="white"/>
      </visual>
      <collision>
        <geometry>
          <mesh filename="package://torobo_resources/meshes/arm/${arm_type}/STL/link7.stl" scale="${col_mesh_scale}"/>
        </geometry>
      </collision>
      <inertial>
        <origin xyz="-0.000973 0.000022 -0.017659"/>	
        <mass value="0.265534"/>	
        <inertia	
          ixx="1.433657e-4" ixy="-5.220000e-8" ixz="5.026000e-7"	
          iyy="1.455343e-4" iyz="-1.360000e-8" izz="2.086642e-4"/>	
      </inertial>
    </link>

    <joint name="${prefix}arm/joint_tip" type="fixed">
      <parent link="${prefix}arm/link_7"/>
      <child link="${prefix}arm/link_tip"/>
      <origin xyz="0 0 0" rpy="0 0 0"/>
    </joint>
    <link name="${prefix}arm/link_tip"/> 

    <!-- Gazebo -->
    <xacro:arm_gazebo_v0 prefix="${prefix}"/>
  
    <!-- =============== Transmission =============== -->
    <simple_transmission name="${prefix}arm/joint_1" reduction="1"/>
    <simple_transmission name="${prefix}arm/joint_2" reduction="1"/>
    <simple_transmission name="${prefix}arm/joint_3" reduction="1"/>
    <simple_transmission name="${prefix}arm/joint_4" reduction="1"/>
    <simple_transmission name="${prefix}arm/joint_5" reduction="1"/>
    <simple_transmission name="${prefix}arm/joint_6" reduction="1"/>
    <simple_transmission name="${prefix}arm/joint_7" reduction="1"/>

  </xacro:macro>

</robot>
