<?xml version="1.0" ?>
<robot name="armdemo">

  <material name="red">
    <color rgba="1.0 0.0 0.0 1.0"/>
  </material>
  <material name="green">
    <color rgba="0.0 1.0 0.0 1.0"/>
  </material>
  <material name="blue">
    <color rgba="0.0 0.0 1.0 1.0"/>
  </material>

  <!-- base(world) -->
  <link name="base_link"/>
  
  <!-- base joint  -->
  <joint name="base_joint" type="fixed">
    <parent link="base_link"/>
    <child link="link1"/>
  </joint>
 
  <!-- Link1 link & joint -->
  <link name="link1">
    <collision>
      <origin rpy="0 0 0" xyz="0 0 0.425"/>
      <geometry>
        <box size="0.09 0.09 0.85"/>
      </geometry>
    </collision>
    <visual>
      <origin rpy="0 0 0" xyz="0 0 0.425"/>
      <geometry>
        <box size="0.09 0.09 0.85"/>
      </geometry>
      <material name="red"/>
    </visual>
    <inertial>
      <origin rpy="0 0 0" xyz="0 0 0"/>
      <mass value="50"/>
      <inertia ixx="0" ixy="0.1" ixz="0.0" iyy="1" iyz="0.0" izz="0.1"/>
    </inertial>
  </link>
   <joint name="joint1" type="revolute">
    <parent link="link1"/>
    <child link="link2"/>
    <origin rpy="0 0 0" xyz="0 0 0.85"/>
   
    <axis xyz="0 0 1"/>
    <dynamics damping="0.05"/>
    <limit effort="30" lower="-0.5" upper="2.56" velocity="1.74"/>
  </joint>
  
  <!-- Link2 link & joint -->
  <link name="link2">
    <collision>
      <origin rpy="0 0 0" xyz="-0.045 0 0.035"/>
      <geometry>
        <box size="0.09 0.09 0.07"/>
      </geometry>
    </collision>
    <visual>
      <origin rpy="0 0 0" xyz="-0.045 0 0.035"/>
      <geometry>
        <box size="0.09 0.09 0.07"/>
      </geometry>
      <material name="blue"/>
    </visual>
    <inertial>
      <origin rpy="0 0 0" xyz="0 0 0.1"/>
      <mass value="0.1"/>
      <inertia ixx="0.01" ixy="0.0" ixz="0.0" iyy="0.01" iyz="0.0" izz="0.01"/>
    </inertial>
  </link>
  <!-- joint2 -->
  <joint name="joint2" type="revolute">
    <parent link="link2"/>
    <child link="link3"/>
    <origin rpy="0 0 0" xyz="0 0 0.07"/>
   
    <axis xyz="1 0 0"/>
    <dynamics damping="0.05"/>
    <limit effort="30" lower="-1.65" upper="0.27" velocity="1.74"/>
  </joint>
  
  <!-- Link3 link & joint -->
 
  <link name="link3">
    <collision>
      <origin rpy="0 0 0" xyz="0.045 0 0.075"/>
      <geometry>
        <box size="0.09 0.09 0.15"/>
      </geometry>
    </collision>
    <visual>
      <origin rpy="0 0 0" xyz="0.045 0 0.075"/>
      <geometry>
        <box size="0.09 0.09 0.15"/>
      </geometry>
      <material name="red"/>
    </visual>
    <inertial>
      <origin rpy="0 0 0" xyz="0.045 0 0.1"/>
      <mass value="0.1"/>
       <inertia ixx="0.01" ixy="0.0" ixz="0.0" iyy="0.01" iyz="0.0" izz="0.01"/>
    </inertial>
  </link>
  <!-- joint3 -->
  <joint name="joint3" type="revolute">
    <parent link="link3"/>
    <child link="link4"/>
    <origin rpy="0 0 0" xyz="0 0 0.15"/>

    <axis xyz="0 0 1"/>
    <dynamics damping="0.1"/>
    <limit effort="30" lower="-2.87" upper="2.87" velocity="2.09"/>
  </joint>

  <!-- Link4 link & joint -->
 
  <link name="link4">
    <collision>
      <origin rpy="0 0 0" xyz="0.045 0 0.075"/>
      <geometry>
        <box size="0.09 0.09 0.15"/>
      </geometry>
    </collision>
    <visual>
      <origin rpy="0 0 0" xyz="0.045 0 0.075"/>
      <geometry>
        <box size="0.09 0.09 0.15"/>
      </geometry>
      <material name="blue"/>
    </visual>
    <inertial>
      <origin rpy="0 0 0" xyz="0 0 0.1"/>
      <mass value="0.1"/>
       <inertia ixx="0.01" ixy="0.0" ixz="0.0" iyy="0.01" iyz="0.0" izz="0.01"/>
    </inertial>
  </link>
  <joint name="joint4" type="revolute">
    <parent link="link4"/>
    <child link="link5"/>
    <origin rpy="0 0 0" xyz="0 0 0.15"/>
 
    <axis xyz="1 0 0"/>
    <dynamics damping="0.1"/>
    <limit effort="30" lower="-2.18" upper="2.18" velocity="2.09"/>
  </joint>

  <!-- Link5 link & joint -->
  <link name="link5">
        <collision>
      <origin rpy="0 0 0" xyz="-0.045 0 0.075"/>
      <geometry>
        <box size="0.09 0.09 0.15"/>
      </geometry>
    </collision>
    <visual>
      <origin rpy="0 0 0" xyz="-0.045 0 0.075"/>
      <geometry>
        <box size="0.09 0.09 0.15"/>
      </geometry>
      <material name="red"/>
    </visual>
    <inertial>
      <origin rpy="0 0 0" xyz="0 0 0.1"/>
      <mass value="0.1"/>
       <inertia ixx="0.01" ixy="0.0" ixz="0.0" iyy="0.01" iyz="0.0" izz="0.01"/>
    </inertial>
  </link>
  <joint name="joint5" type="revolute">
    <parent link="link5"/>
    <child link="link6"/>
    <origin rpy="0 0 0" xyz="0 0 0.15"/>
 
    <axis xyz="0 0 1"/>
    <dynamics damping="0.1"/>
    <limit effort="30" lower="-2.87" upper="2.87" velocity="2.79"/>
  </joint>
  
  <!-- Link6 link & joint -->
  
  <link name="link6">
    <collision>
      <origin rpy="0 0 0" xyz="-0.045 0 0.075"/>
      <geometry>
        <box size="0.09 0.09 0.15"/>
      </geometry>
    </collision>
    <visual>
      <origin rpy="0 0 0" xyz="-0.045 0 0.075"/>
      <geometry>
        <box size="0.09 0.09 0.15"/>
      </geometry>
      <material name="blue"/>
    </visual>
    <inertial>
      <origin rpy="0 0 0" xyz="0 0 0.1"/>
      <mass value="0.1"/>
       <inertia ixx="0.01" ixy="0.0" ixz="0.0" iyy="0.01" iyz="0.0" izz="0.01"/>
    </inertial>
  </link>
  <joint name="joint6" type="revolute">
    <parent link="link6"/>
    <child link="link7"/>
    <origin rpy="0 0 0" xyz="0 0 0.15"/>
    <axis xyz="1 0 0"/>
    <dynamics damping="0.1"/>
    <limit effort="30" lower="-2.09" upper="2.09" velocity="2.79"/>
  </joint>

  <!-- Link7 link & joint -->
  <link name="link7">
    <collision>
      <origin rpy="0 0 0" xyz="0.045 0 0.075"/>
      <geometry>
        <box size="0.09 0.09 0.15"/>
      </geometry>
    </collision>
    <visual>
      <origin rpy="0 0 0" xyz="0.045 0 0.075"/>
      <geometry>
        <box size="0.09 0.09 0.15"/>
      </geometry>
      <material name="red"/>
    </visual>
    <inertial>
      <origin rpy="0 0 0" xyz="0 0 0.1"/>
      <mass value="0.1"/>
       <inertia ixx="0.01" ixy="0.0" ixz="0.0" iyy="0.01" iyz="0.0" izz="0.01"/>
    </inertial>
  </link>
  <joint name="joint7" type="revolute">
    <parent link="link7"/>
    <child link="link8"/>
    <origin rpy="0 0 0" xyz="0 0 0.15"/>
    <axis xyz="0 0 1"/>
    <dynamics damping="0.1"/>
    <limit effort="30" lower="-2.96" upper="2.96" velocity="4.18"/>
  </joint>

 <!-- Link8 (end effector)-->
  <link name="link8">
    <collision>
      <origin rpy="0 0 0" xyz="0 0 0.01"/>
      <geometry>
        <box size="0.09 0.09 0.02"/>
      </geometry>
    </collision>
    <visual>
      <origin rpy="0 0 0" xyz="0 0 0.01"/>
      <geometry>
        <box size="0.09 0.09 0.02"/>
      </geometry>
      <material name="blue"/>
    </visual>
    <inertial>
      <origin rpy="0 0 0" xyz="0 0 0.01"/>
      <mass value="0.1"/>
        <inertia ixx="0.01" ixy="0.0" ixz="0.0" iyy="0.01" iyz="0.0" izz="0.01"/>
    </inertial>
  </link>

  <transmission name="link1_trans">
    <type>transmission_interface/SimpleTransmission</type>
      <joint name="joint1">
      <hardwareInterface>hardware_interface/EffortJointInterface</hardwareInterface>
    </joint>
    <actuator name="link1_motor">
      <hardwareInterface>hardware_interface/EffortJointInterface</hardwareInterface>
      <mechanicalReduction>1</mechanicalReduction>
    </actuator>
  </transmission>
  <transmission name="link2_trans">
    <type>transmission_interface/SimpleTransmission</type>
      <joint name="joint2">
      <hardwareInterface>hardware_interface/EffortJointInterface</hardwareInterface>
    </joint>
    <actuator name="link2_motor">
      <hardwareInterface>hardware_interface/EffortJointInterface</hardwareInterface>
      <mechanicalReduction>1</mechanicalReduction>
    </actuator>
  </transmission>
  <transmission name="link3_trans">
    <type>transmission_interface/SimpleTransmission</type>
      <joint name="joint3">
      <hardwareInterface>hardware_interface/EffortJointInterface</hardwareInterface>
    </joint>
    <actuator name="link3_motor">
      <hardwareInterface>hardware_interface/EffortJointInterface</hardwareInterface>
      <mechanicalReduction>1</mechanicalReduction>
    </actuator>
  </transmission>
  <transmission name="link4_trans">
    <type>transmission_interface/SimpleTransmission</type>
      <joint name="joint4">
      <hardwareInterface>hardware_interface/EffortJointInterface</hardwareInterface>
    </joint>
    <actuator name="link4_motor">
      <hardwareInterface>hardware_interface/EffortJointInterface</hardwareInterface>
      <mechanicalReduction>1</mechanicalReduction>
    </actuator>
  </transmission>
  <transmission name="link5_trans">
    <type>transmission_interface/SimpleTransmission</type>
      <joint name="joint5">
      <hardwareInterface>hardware_interface/EffortJointInterface</hardwareInterface>
    </joint>
    <actuator name="link5_motor">
      <hardwareInterface>hardware_interface/EffortJointInterface</hardwareInterface>
      <mechanicalReduction>1</mechanicalReduction>
    </actuator>
  </transmission>
  <transmission name="link6_trans">
    <type>transmission_interface/SimpleTransmission</type>
      <joint name="joint6">
      <hardwareInterface>hardware_interface/EffortJointInterface</hardwareInterface>
    </joint>
    <actuator name="link6_motor">
      <hardwareInterface>hardware_interface/EffortJointInterface</hardwareInterface>
      <mechanicalReduction>1</mechanicalReduction>
    </actuator>
  </transmission>
  <transmission name="link7_trans">
    <type>transmission_interface/SimpleTransmission</type>
      <joint name="joint7">
      <hardwareInterface>hardware_interface/EffortJointInterface</hardwareInterface>
    </joint>
    <actuator name="link7_motor">
      <hardwareInterface>hardware_interface/EffortJointInterface</hardwareInterface>
      <mechanicalReduction>1</mechanicalReduction>
    </actuator>
  </transmission>
  <gazebo>
    <plugin name="gazebo_ros_control" filename="libgazebo_ros_control.so">
      <robotNamespace>/</robotNamespace>
      <robotSimType>gazebo_ros_control/DefaultRobotHWSim</robotSimType>
      <legacyModeNS>true</legacyModeNS>
    </plugin>
  </gazebo>

</robot>
