<?xml version="1.0" ?>
<robot name="armdemo">

  <material name="red">
    <color rgba="1.0 0.0 0.0 1.0"/>
  </material>
  <material name="green">
    <color rgba="0.0 1.0 0.0 1.0"/>
  </material>
  <material name="blue">
    <color rgba="0.0 0.0 1.0 1.0"/>
  </material>

  <link name="world"/>

  <joint name="world2base" type="fixed">
    <parent link="world"/>
    <child link="base"/>
  </joint>

  <link name="base"/>
  <joint name="fixed" type="fixed">
    <parent link="base"/>
    <child link="link1"/>
  </joint>

  <!-- Link 1 -->
  <link name="link1">
    <collision>
      <origin rpy="0 0 0" xyz="0 0 0.05"/>
      <geometry>
        <box size="0.12 0.12 0.1"/>
      </geometry>
    </collision>
    <visual>
      <origin rpy="0 0 0" xyz="0 0 0.05"/>
      <geometry>
        <box size="0.12 0.12 0.1"/>
      </geometry>
      <material name="red"/>
    </visual>
    <inertial>
      <origin rpy="0 0 0" xyz="0 0 0.05"/>
      <mass value="1.24"/>
      <inertia ixx="0.002524" ixy="0.0" ixz="0.0" iyy="0.002524" iyz="0.0" izz="0.002979"/>
    </inertial>
  </link>
  <joint name="joint1" type="revolute">
    <parent link="link1"/>
    <child link="link2"/>
    <origin rpy="0 0 0" xyz="0 0 0.1"/>
    <axis xyz="0 0 1"/>
    <limit effort="30" lower="-2.617" upper="2.617" velocity="1.571"/>
  </joint>
  
  <transmission name="trans1">
    <type>transmission_interface/SimpleTransmission</type>
    <joint name="joint1"> 
      <hardwareInterface>hardware_interface/EffortJointInterface</hardwareInterface>
    </joint>
    <actuator name="motor1">
       <hardwareInterface>EffortJointInterface</hardwareInterface>
      <mechanicalReduction>1</mechanicalReduction>
    </actuator>
  </transmission>

  <!-- Link 2 -->
  <link name="link2">
    <collision>
      <origin rpy="0 0 0" xyz="0 0 0.29"/>
      <geometry>
        <box size="0.08 0.08 0.58"/>
      </geometry>
    </collision>
    <visual>
      <origin rpy="0 0 0" xyz="0 0 0.29"/>
      <geometry>
        <box size="0.08 0.08 0.58"/>
      </geometry>
      <material name="blue"/>
    </visual>
    <inertial>
      <origin rpy="0 0 0" xyz="0 0 0.29"/>
      <mass value="3.20"/>
      <inertia ixx="0.09142" ixy="0.0" ixz="0.0" iyy="0.09142" iyz="0.0" izz="0.003413"/>
    </inertial>
  </link>
  <joint name="joint2" type="revolute">
    <parent link="link2"/>
    <child link="link3"/>
    <origin rpy="0 0 0" xyz="0 0 0.58"/>
    <axis xyz="0 1 0"/>
    <limit effort="30" lower="0" upper="2.617" velocity="1.571"/>
  </joint>

  <transmission name="trans1">
    <type>transmission_interface/SimpleTransmission</type>
    <joint name="joint2"> 
      <hardwareInterface>hardware_interface/EffortJointInterface</hardwareInterface>
    </joint>
    <actuator name="motor2">
       <hardwareInterface>EffortJointInterface</hardwareInterface>
      <mechanicalReduction>1</mechanicalReduction>
    </actuator>
  </transmission>

  <!-- Link 3 -->
  <link name="link3">
    <collision>
      <origin rpy="0 0 0" xyz="0 0 0.275"/>
      <geometry>
        <box size="0.08 0.08 0.55"/>
      </geometry>
    </collision>
    <visual>
      <origin rpy="0 0 0" xyz="0 0 0.275"/>
      <geometry>
        <box size="0.08 0.08 0.55"/>
      </geometry>
      <material name="red"/>
    </visual>
    <inertial>
      <origin rpy="0 0 0" xyz="0 0 0.275"/>
      <mass value="3.03"/>
      <inertia ixx="0.078118" ixy="0.0" ixz="0.0" iyy="0.078118" iyz="0.0" izz="0.003237"/>
    </inertial>
  </link>
  <joint name="joint3" type="revolute">
    <parent link="link3"/>
    <child link="link4"/>
    <origin rpy="0 0 0" xyz="0 0 0.55"/>
    <axis xyz="0 1 0"/>
    <limit effort="30" lower="0" upper="2.617" velocity="1.571"/>
  </joint>
 
  <transmission name="trans3">
    <type>transmission_interface/SimpleTransmission</type>
    <joint name="joint3"> 
      <hardwareInterface>hardware_interface/EffortJointInterface</hardwareInterface>
    </joint>
    <actuator name="motor3">
       <hardwareInterface>EffortJointInterface</hardwareInterface>
      <mechanicalReduction>1</mechanicalReduction>
    </actuator>
  </transmission>

  <!-- Link 4 -->
  <link name="link4">
    <collision>
      <origin rpy="0 0 0" xyz="0 0 0.075"/>
      <geometry>
        <box size="0.07 0.07 0.15"/>
      </geometry>
    </collision>
    <visual>
      <origin rpy="0 0 0" xyz="0 0 0.075"/>
      <geometry>
        <box size="0.07 0.07 0.15"/>
      </geometry>
      <material name="blue"/>
    </visual>
    <inertial>
      <origin rpy="0 0 0" xyz="0 0 0.075"/>
      <mass value="0.63"/>
      <inertia ixx="0.001446" ixy="0.0" ixz="0.0" iyy="0.001446" iyz="0.0" izz="0.000517"/>
    </inertial>
  </link>
  <joint name="joint4" type="revolute">
    <parent link="link4"/>
    <child link="link5"/>
    <origin rpy="0 0 0" xyz="0 0 0.15"/>
    <axis xyz="0 0 1"/>
    <limit effort="30" lower="-2.617" upper="2.617" velocity="1.571"/>
  </joint>
 
  <transmission name="trans4">
    <type>transmission_interface/SimpleTransmission</type>
    <joint name="joint4"> 
      <hardwareInterface>hardware_interface/EffortJointInterface</hardwareInterface>
    </joint>
    <actuator name="motor4">
       <hardwareInterface>EffortJointInterface</hardwareInterface>
      <mechanicalReduction>1</mechanicalReduction>
    </actuator>
  </transmission>

  <!-- Link 5 -->
  <link name="link5">
        <collision>
      <origin rpy="0 0 0" xyz="0 0 0.05"/>
      <geometry>
        <box size="0.07 0.07 0.1"/>
      </geometry>
    </collision>
    <visual>
      <origin rpy="0 0 0" xyz="0 0 0.05"/>
      <geometry>
        <box size="0.07 0.07 0.1"/>
      </geometry>
      <material name="blue"/>
    </visual>
    <inertial>
      <origin rpy="0 0 0" xyz="0 0 0.05"/>
      <mass value="0.42"/>
      <inertia ixx="0.000524" ixy="0.0" ixz="0.0" iyy="0.000524" iyz="0.0" izz="0.000345"/>
    </inertial>
  </link>
  <joint name="joint5" type="revolute">
    <parent link="link5"/>
    <child link="link6"/>
    <origin rpy="0 0 0" xyz="0 0 0.1"/>
    <axis xyz="0 1 0"/>
    <limit effort="30" lower="0" upper="2.617" velocity="1.571"/>
  </joint>

  <transmission name="trans5">
    <type>transmission_interface/SimpleTransmission</type>
    <joint name="joint5"> 
      <hardwareInterface>hardware_interface/EffortJointInterface</hardwareInterface>
    </joint>
    <actuator name="motor5">
       <hardwareInterface>EffortJointInterface</hardwareInterface>
      <mechanicalReduction>1</mechanicalReduction>
    </actuator>
  </transmission>

  <!-- Link 6 -->
  <link name="link6">
    <collision>
      <origin rpy="0 0 0" xyz="0 0 0.21"/>
      <geometry>
        <box size="0.08 0.08 0.42"/>
      </geometry>
    </collision>
    <visual>
      <origin rpy="0 0 0" xyz="0 0 0.21"/>
      <geometry>
        <box size="0.08 0.08 0.42"/>
      </geometry>
      <material name="blue"/>
    </visual>
    <inertial>
      <origin rpy="0 0 0" xyz="0 0 0.21"/>
      <mass value="2.32"/>
      <inertia ixx="0.035302" ixy="0.0" ixz="0.0" iyy="0.035302" iyz="0.0" izz="0.002471"/>
    </inertial>
  </link>
  <joint name="joint6" type="revolute">
    <parent link="link6"/>
    <child link="link7"/>
    <origin rpy="0 0 0" xyz="0 0 0.42"/>
    <axis xyz="0 1 0"/>
    <limit effort="30" lower="0" upper="2.617" velocity="1.571"/>
  </joint>

  <transmission name="trans6">
    <type>transmission_interface/SimpleTransmission</type>
    <joint name="joint6"> 
      <hardwareInterface>hardware_interface/EffortJointInterface</hardwareInterface>
    </joint>
    <actuator name="motor6">
       <hardwareInterface>EffortJointInterface</hardwareInterface>
      <mechanicalReduction>1</mechanicalReduction>
    </actuator>
  </transmission>

  <link name="link7">
    <collision>
      <origin rpy="0 0 0" xyz="0 0 0.05"/>
      <geometry>
        <box size="0.07 0.07 0.1"/>
      </geometry>
    </collision>
    <visual>
      <origin rpy="0 0 0" xyz="0 0 0.05"/>
      <geometry>
        <box size="0.07 0.07 0.1"/>
      </geometry>
      <material name="blue"/>
    </visual>
    <inertial>
      <origin rpy="0 0 0" xyz="0 0 0.05"/>
      <mass value="0.42"/>
      <inertia ixx="0.000524" ixy="0.0" ixz="0.0" iyy="0.000524" iyz="0.0" izz="0.000345"/>
    </inertial>
  </link>
  <joint name="joint7" type="revolute">
    <parent link="link7"/>
    <child link="link8"/>
    <origin rpy="0 0 0" xyz="0 0 0.1"/>
    <axis xyz="0 0 1"/>
    <limit effort="30" lower="-2.617" upper="2.617" velocity="1.571"/>
  </joint>

  <transmission name="trans7">
    <type>transmission_interface/SimpleTransmission</type>
    <joint name="joint7"> 
      <hardwareInterface>hardware_interface/EffortJointInterface</hardwareInterface>
    </joint>
    <actuator name="motor7">
       <hardwareInterface>EffortJointInterface</hardwareInterface>
      <mechanicalReduction>1</mechanicalReduction>
    </actuator>
  </transmission>

 <!-- Link 8 (end effector)-->
  <link name="link8">
    <collision>
      <origin rpy="0 0 0" xyz="0 0 0.025"/>
      <geometry>
        <box size="0.05 0.05 0.05"/>
      </geometry>
    </collision>
    <visual>
      <origin rpy="0 0 0" xyz="0 0 0.025"/>
      <geometry>
        <box size="0.05 0.05 0.05"/>
      </geometry>
      <material name="red"/>
    </visual>
    <inertial>
      <origin rpy="0 0 0" xyz="0 0 0.25"/>
      <mass value="0.1"/>
      <inertia ixx="0.000044" ixy="0.0" ixz="0.0" iyy="0.000044" iyz="0.0" izz="0.000044"/>
    </inertial>
  </link>

  <gazebo>
    <plugin name="gazebo_ros_control" filename="libgazebo_ros_control.so">
      <robotNamespace>/</robotNamespace>
　　　<robotSimType>gazebo_ros_control/DefaultRobotHWSim</robotSimType>
      <legacyModeNS>true</legacyModeNS>
    </plugin>
  </gazebo>
</robot>
